Workbook
Name UPDATE: 'Data Sheet'!$E$1

Sheet Data Sheet
A1: COMPANY NAME | B1: ITC LTD | E1: =IF(B2<>B3, "A NEW VERSION OF THE WORKSHEET IS AVAILABLE", "")
A2: LATEST VERSION | B2: 2.1 | E2: PLEASE DO NOT MAKE ANY CHANGES TO THIS SHEET
A3: CURRENT VERSION | B3: 2.1
A5: META
A6: Number of shares | B6: =IF(B9>0, B9/B8, 0) -> 1252.8766
A7: Face Value | B7: 1
A8: Current Price | B8: 403
A9: Market Capitalization | B9: 504909.25
A15: PROFIT & LOSS
A16: Report Date | B16: 42460 | C16: 42825 | D16: 43190 | E16: 43555 | F16: 43921 | G16: 44286 | H16: 44651 | I16: 45016 | J16: 45382 | K16: 45747
A17: Sales | B17: 39192.1 | C17: 42767.6 | D17: 43448.94 | E17: 48339.58 | F17: 49387.7 | G17: 49257.45 | H17: 60644.54 | I17: 70919.03 | J17: 67931.94 | K17: 75323.34
A18: Raw Material Cost | B18: 13763.88 | C18: 15456.59 | D18: 14827.72 | E18: 17623.52 | F18: 18048.6 | G18: 20776.71 | H18: 27071.07 | I18: 29364.36 | J18: 27348.57 | K18: 32704.37
A19: Change in Inventory | B19: 195.38 | C19: -592.57 | D19: -1027.76 | E19: 203.19 | F19: 703.13 | G19: 645.27 | H19: 686 | I19: 358.59 | J19: 367.77 | K19: 725.65
A20: Power and Fuel | B20: 571.88 | C20: 584.33 | D20: 653.5 | E20: 746.73 | F20: 780.85 | G20: 699.56 | H20: 889.77 | I20: 1232.34 | J20: 952.9 | K20: 975.35
A21: Other Mfr. Exp | B21: 1581.59 | C21: 1683.9 | D21: 1697.62 | E21: 1871.01 | F21: 1908.29 | G21: 1587.18 | H21: 1887.67 | I21: 2327.8 | J21: 2183.76 | K21: 2345.36
A22: Employee Cost | B22: 3440.97 | C22: 3631.73 | D22: 3760.9 | E22: 4177.88 | F22: 4295.79 | G22: 4463.33 | H22: 4890.55 | I22: 5736.22 | J22: 5548.53 | K22: 6169.78
A23: Selling and admin | B23: 4261.78 | C23: 4179.74 | D23: 3954.87 | E23: 4546.39 | F23: 4488.63 | G23: 4236.77 | H23: 4858.38 | I23: 5604.08 | J23: 5312.45 | K23: 5793.29
A24: Other Expenses | B24: 1235.89 | C24: 1169.23 | D24: 1005.98 | E24: 1039.85 | F24: 1225.13 | G24: 1074.39 | H24: 1109.95 | I24: 1308.56 | J24: 1765.97 | K24: 2221.39
A25: Other Income | B25: 1483.11 | C25: 1758.63 | D25: 2239.81 | E25: 2080.44 | F25: 2417.32 | G25: 2576.95 | H25: 1909.72 | I25: 2097.64 | J25: 3330.45 | K25: 17794.88
A26: Depreciation | B26: 1077.4 | C26: 1152.79 | D26: 1236.28 | E26: 1396.61 | F26: 1644.91 | G26: 1645.59 | H26: 1732.41 | I26: 1809.01 | J26: 1518.05 | K26: 1646.32
A27: Interest | B27: 78.13 | C27: 49.03 | D27: 115.01 | E27: 71.4 | F27: 81.38 | G27: 57.97 | H27: 59.99 | I27: 77.77 | J27: 39.11 | K27: 45.06
... A31: Dividend Amount | B31: 6840.12 | C31: 5770.02 | D31: 6285.21 | E31: 7048.7 | F31: 12476.58 | G31: 13231.96 | H31: 14171.8 | I31: 19263.4 | J31: 17166.46 | K31: 17957.73
A40: Quarters
A41: Report Date | B41: 45107 | C41: 45199 | D41: 45291 | E41: 45382 | F41: 45473 | G41: 45565 | H41: 45657 | I41: 45747 | J41: 45838 | K41: 45930
A42: Sales | B42: 17164.46 | C42: 17774.47 | D42: 17195.24 | E42: 17037.8 | F42: 17777.81 | G42: 19990.36 | H42: 18790.17 | I42: 18765 | J42: 21494.79 | K42: 19501.63
A43: Expenses | B43: 10494.39 | C43: 11320.23 | D43: 10985.01 | E43: 10735.73 | F43: 11232.97 | G43: 13438.28 | H43: 12428.27 | I43: 12245.61 | J43: 14678.32 | K43: 12806.94
A44: Other Income | B44: 722.3 | C44: 673.5 | D44: 820.26 | E44: 868 | F44: 771.13 | G44: 690.31 | H44: 803.4 | I44: 15391.28 | J44: 750.97 | K44: 738.84
A45: Depreciation | B45: 442.46 | C45: 453.04 | D45: 384.04 | E45: 385.09 | F45: 403.13 | G45: 416.18 | H45: 415.98 | I45: 411.03 | J45: 422.96 | K45: 434.8
A46: Interest | B46: 9.9 | C46: 9.87 | D46: 11.94 | E46: 10.72 | F46: 9.6 | G46: 14.73 | H46: 9.82 | I46: 10.91 | J46: 16.47 | K46: 20.05
A47: Profit before tax | B47: 6940.01 | C47: 6664.83 | D47: 6634.51 | E47: 6774.26 | F47: 6903.24 | G47: 6811.48 | H47: 6739.5 | I47: 21488.73 | J47: 7128.01 | K47: 6978.68
A48: Tax | B48: 1759.89 | C48: 1700.31 | D48: 1227.99 | E48: 1583.55 | F48: 1726.25 | G48: 1757.05 | H48: 1726.32 | I48: 1680.85 | J48: 1784.6 | K48: 1792.13
A49: Net profit | B49: 5104.93 | C49: 4898.07 | D49: 5335.23 | E49: 5120.55 | F49: 5091.59 | G49: 4992.87 | H49: 4934.8 | I49: 19727.37 | J49: 5244.2 | K49: 5126.11
A50: Operating Profit | B50: 6670.07 | C50: 6454.24 | D50: 6210.23 | E50: 6302.07 | F50: 6544.84 | G50: 6552.08 | H50: 6361.9 | I50: 6519.39 | J50: 6816.47 | K50: 6694.69
A55: BALANCE SHEET
A56: Report Date | B56: 42460 | C56: 42825 | D56: 43190 | E56: 43555 | F56: 43921 | G56: 44286 | H56: 44651 | I56: 45016 | J56: 45382 | K56: 45747
A57: Equity Share Capital | B57: 804.72 | C57: 1214.74 | D57: 1220.43 | E57: 1225.86 | F57: 1229.22 | G57: 1230.88 | H57: 1232.33 | I57: 1242.8 | J57: 1248.47 | K57: 1251.41
A58: Reserves | B58: 41874.8 | C58: 45198.19 | D58: 51289.68 | E58: 57915.01 | F58: 64044.04 | G58: 59116.46 | H58: 61223.24 | I58: 67912.46 | J58: 73258.53 | K58: 68778.64
A59: Borrowings | B59: 83.78 | C59: 45.72 | D59: 35.92 | E59: 13.44 | F59: 277.45 | G59: 270.83 | H59: 249.44 | I59: 306.04 | J59: 303.43 | K59: 284.54
A60: Other Liabilities | B60: 8888.04 | C60: 9439.67 | D60: 11694.85 | E60: 12584.73 | F60: 11760.04 | G60: 13142.59 | H60: 14491.01 | I60: 16369.66 | J60: 16943.54 | K60: 17688.11
A61: Total | B61: 51651.34 | C61: 55898.32 | D61: 64240.88 | E61: 71739.04 | F61: 77310.75 | G61: 73760.76 | H61: 77196.02 | I61: 85830.96 | J61: 91753.97 | K61: 88002.7
...

Sheet Historical Financial Statement
B2: ="Historical Financial Statement - "&'Data Sheet'!B1 -> Historical Financial Statement - ITC LTD
B3: Year | D3: ='Data Sheet'!B16 -> 42460 | E3: ='Data Sheet'!C16 -> 42825 | F3: ='Data Sheet'!D16 -> 43190 | G3: ='Data Sheet'!E16 -> 43555 | H3: ='Data Sheet'!F16 -> 43921 | I3: ='Data Sheet'!G16 -> 44286 | J3: ='Data Sheet'!H16 -> 44651 | K3: ='Data Sheet'!I16 -> 45016 | ... M3: ='Data Sheet'!K16 -> 45747
B5: ="Income Statement - "&'Data Sheet'!B1 -> Income Statement - ITC LTD
B6: Sales | D6: ='Data Sheet'!B17 -> 39192.1 | E6: ='Data Sheet'!C17 -> 42767.6 | F6: ='Data Sheet'!D17 -> 43448.94 | G6: ='Data Sheet'!E17 -> 48339.58 | H6: ='Data Sheet'!F17 -> 49387.7 | I6: ='Data Sheet'!G17 -> 49257.45 | J6: ='Data Sheet'!H17 -> 60644.54 | K6: ='Data Sheet'!I17 -> 70919.03 | ... M6: ='Data Sheet'!K17 -> 75323.34
B7: Sales Growth | D7: NA | E7: =(E6/D6)-1 -> 0.09123012 | F7: =(F6/E6)-1 -> 0.015931219 | G7: =(G6/F6)-1 -> 0.11256063 | H7: =(H6/G6)-1 -> 0.021682439 | I7: =(I6/H6)-1 -> -0.0026372963 | J7: =(J6/I6)-1 -> 0.23117498 | K7: =(K6/J6)-1 -> 0.16942152 | L7: =(L6/K6)-1 -> -0.042119724 | M7: =(M6/L6)-1 -> 0.10880596
B9: COGS | D9: =('Data Sheet'!B18+'Data Sheet'!B20+'Data Sheet'!B21+'Data Sheet'!B22)-'Data Sheet'!B19 -> 19162.94 | E9: =('Data Sheet'!C18+'Data Sheet'!C20+'Data Sheet'!C21+'Data Sheet'!C22)-'Data Sheet'!C19 -> 21949.12 | F9: =('Data Sheet'!D18+'Data Sheet'!D20+'Data Sheet'!D21+'Data Sheet'!D22)-'Data Sheet'!D19 -> 21967.5 | G9: =('Data Sheet'!E18+'Data Sheet'!E20+'Data Sheet'!E21+'Data Sheet'!E22)-'Data Sheet'!E19 -> 24215.95 | H9: =('Data Sheet'!F18+'Data Sheet'!F20+'Data Sheet'!F21+'Data Sheet'!F22)-'Data Sheet'!F19 -> 24330.4 | I9: =('Data Sheet'!G18+'Data Sheet'!G20+'Data Sheet'!G21+'Data Sheet'!G22)-'Data Sheet'!G19 -> 26881.51 | J9: =('Data Sheet'!H18+'Data Sheet'!H20+'Data Sheet'!H21+'Data Sheet'!H22)-'Data Sheet'!H19 -> 34053.06 | K9: =('Data Sheet'!I18+'Data Sheet'!I20+'Data Sheet'!I21+'Data Sheet'!I22)-'Data Sheet'!I19 -> 38302.13 | ... M9: =('Data Sheet'!K18+'Data Sheet'!K20+'Data Sheet'!K21+'Data Sheet'!K22)-'Data Sheet'!K19 -> 41469.21
B10: COGS % Sales | D10: =D9/D6 -> 0.48894905 | E10: =E9/E6 -> 0.51321842 | F10: =F9/F6 -> 0.50559346 | G10: =G9/G6 -> 0.50095491 | H10: =H9/H6 -> 0.49264088 | I10: =I9/I6 -> 0.54573491 | J10: =J9/J6 -> 0.56151898 | K10: =K9/K6 -> 0.54008254 | ... M10: =M9/M6 -> 0.55054927
B12: Gross Profit | D12: =D6-D9 -> 20029.16 | E12: =E6-E9 -> 20818.48 | F12: =F6-F9 -> 21481.44 | G12: =G6-G9 -> 24123.63 | H12: =H6-H9 -> 25057.3 | I12: =I6-I9 -> 22375.94 | J12: =J6-J9 -> 26591.48 | K12: =K6-K9 -> 32616.9 | ... M12: =M6-M9 -> 33854.13
B13: Gross Margins | D13: =D12/D6 -> 0.51105095 | E13: =E12/E6 -> 0.48678158 | F13: =F12/F6 -> 0.49440654 | G13: =G12/G6 -> 0.49904509 | H13: =H12/H6 -> 0.50735912 | I13: =I12/I6 -> 0.45426509 | J13: =J12/J6 -> 0.43848102 | K13: =K12/K6 -> 0.45991746 | ... M13: =M12/M6 -> 0.44945073
B15: Selling and General Expenses | D15: =('Data Sheet'!B23+'Data Sheet'!B24) -> 5497.67 | E15: =('Data Sheet'!C23+'Data Sheet'!C24) -> 5348.97 | F15: =('Data Sheet'!D23+'Data Sheet'!D24) -> 4960.85 | G15: =('Data Sheet'!E23+'Data Sheet'!E24) -> 5586.24 | H15: =('Data Sheet'!F23+'Data Sheet'!F24) -> 5713.76 | I15: =('Data Sheet'!G23+'Data Sheet'!G24) -> 5311.16 | J15: =('Data Sheet'!H23+'Data Sheet'!H24) -> 5968.33 | K15: =('Data Sheet'!I23+'Data Sheet'!I24) -> 6912.64 | ... M15: =('Data Sheet'!K23+'Data Sheet'!K24) -> 8014.68
B16: S&G Exp % Sales | D16: =D15/D6 -> 0.14027495 | E16: =E15/E6 -> 0.12507061 | F16: =F15/F6 -> 0.11417655 | G16: =G15/G6 -> 0.11556244 | H16: =H15/H6 -> 0.11569196 | I16: =I15/I6 -> 0.1078245 | J16: =J15/J6 -> 0.09841496 | K16: =K15/K6 -> 0.097472286 | ... M16: =M15/M6 -> 0.10640367
B18: EBITDA | D18: =D12-D15 -> 14531.49 | E18: =E12-E15 -> 15469.51 | F18: =F12-F15 -> 16520.59 | G18: =G12-G15 -> 18537.39 | H18: =H12-H15 -> 19343.54 | I18: =I12-I15 -> 17064.78 | J18: =J12-J15 -> 20623.15 | K18: =K12-K15 -> 25704.26 | ... M18: =M12-M15 -> 25839.45
B19: EBITDA Margins | D19: =D18/D6 -> 0.370776 | E19: =E18/E6 -> 0.36171097 | F19: =F18/F6 -> 0.38022999 | G19: =G18/G6 -> 0.38348265 | H19: =H18/H6 -> 0.39166716 | I19: =I18/I6 -> 0.34644059 | J19: =J18/J6 -> 0.34006606 | K19: =K18/K6 -> 0.36244517 | ... M19: =M18/M6 -> 0.34304706
B21: Interest | D21: ='Data Sheet'!B27 -> 78.13 | E21: ='Data Sheet'!C27 -> 49.03 | F21: ='Data Sheet'!D27 -> 115.01 | G21: ='Data Sheet'!E27 -> 71.4 | H21: ='Data Sheet'!F27 -> 81.38 | I21: ='Data Sheet'!G27 -> 57.97 | J21: ='Data Sheet'!H27 -> 59.99 | K21: ='Data Sheet'!I27 -> 77.77 | ... M21: ='Data Sheet'!K27 -> 45.06
B22: Interest % Sales | D22: =D21/D6 -> 0.001993514 | E22: =E21/E6 -> 0.0011464286 | F22: =F21/F6 -> 0.0026470151 | G22: =G21/G6 -> 0.0014770505 | H22: =H21/H6 -> 0.0016477787 | I22: =I21/I6 -> 0.0011768778 | J22: =J21/J6 -> 0.00098920694 | K22: =K21/K6 -> 0.0010966027 | ... M22: =M21/M6 -> 0.00059822095
B24: Depreciation | D24: ='Data Sheet'!B26 -> 1077.4 | E24: ='Data Sheet'!C26 -> 1152.79 | F24: ='Data Sheet'!D26 -> 1236.28 | G24: ='Data Sheet'!E26 -> 1396.61 | H24: ='Data Sheet'!F26 -> 1644.91 | I24: ='Data Sheet'!G26 -> 1645.59 | J24: ='Data Sheet'!H26 -> 1732.41 | K24: ='Data Sheet'!I26 -> 1809.01 | ... M24: ='Data Sheet'!K26 -> 1646.32
B25: Depreciation % Sales | D25: =D24/D6 -> 0.027490234 | E25: =E24/E6 -> 0.026954751 | F25: =F24/F6 -> 0.028453629 | G25: =G24/G6 -> 0.028891645 | H25: =H24/H6 -> 0.033306066 | I25: =I24/I6 -> 0.033407941 | J25: =J24/J6 -> 0.028566628 | K25: =K24/K6 -> 0.025508104 | ... M25: =M24/M6 -> 0.021856705
B27: Earnings Before Tax | D27: =D18-(D21+D24) -> 13375.96 | E27: =E18-(E21+E24) -> 14267.69 | F27: =F18-(F21+F24) -> 15169.3 | G27: =G18-(G21+G24) -> 17069.38 | H27: =H18-(H21+H24) -> 17617.25 | I27: =I18-(I21+I24) -> 15361.22 | J27: =J18-(J21+J24) -> 18830.75 | K27: =K18-(K21+K24) -> 23817.48 | ... M27: =M18-(M21+M24) -> 24148.07
B28: EBT % Sales | D28: =D27/D6 -> 0.34129225 | E28: =E27/E6 -> 0.33360979 | F28: =F27/F6 -> 0.34912935 | G28: =G27/G6 -> 0.35311395 | H28: =H27/H6 -> 0.35671331 | I28: =I27/I6 -> 0.31185577 | J28: =J27/J6 -> 0.31051023 | K28: =K27/K6 -> 0.33584046 | ... M28: =M27/M6 -> 0.32059213
B30: Tax | D30: ='Data Sheet'!B29 -> 5358.21 | E30: ='Data Sheet'!C29 -> 5549.09 | F30: ='Data Sheet'!D29 -> 5916.43 | G30: ='Data Sheet'!E29 -> 6313.92 | H30: ='Data Sheet'!F29 -> 4441.79 | I30: ='Data Sheet'!G29 -> 4555.29 | J30: ='Data Sheet'!H29 -> 5237.34 | K30: ='Data Sheet'!I29 -> 6438.4 | ... M30: ='Data Sheet'!K29 -> 6890.47
B31: Effective Tax Rate | D31: =D30/D27 -> 0.40058508 | E31: =E30/E27 -> 0.38892701 | F31: =F30/F27 -> 0.39002657 | G31: =G30/G27 -> 0.36989744 | H31: =H30/H27 -> 0.25212732 | I31: =I30/I27 -> 0.29654481 | J31: =J30/J27 -> 0.278127 | K31: =K30/K27 -> 0.27032247 | ... M31: =M30/M27 -> 0.28534247
B33: Net Profit | D33: =D27-D30 -> 8017.75 | E33: =E27-E30 -> 8718.6 | F33: =F27-F30 -> 9252.87 | G33: =G27-G30 -> 10755.46 | H33: =H27-H30 -> 13175.46 | I33: =I27-I30 -> 10805.93 | J33: =J27-J30 -> 13593.41 | K33: =K27-K30 -> 17379.08 | ... M33: =M27-M30 -> 17257.6
B34: Net Margins | D34: =D33/D6 -> 0.20457567 | E34: =E33/E6 -> 0.20385993 | F34: =F33/F6 -> 0.21295963 | G34: =G33/G6 -> 0.222498 | H34: =H33/H6 -> 0.26677614 | I34: =I33/I6 -> 0.21937656 | J34: =J33/J6 -> 0.22414895 | K34: =K33/K6 -> 0.24505524 | ... M34: =M33/M6 -> 0.22911358
B36: No. of Equity Shares | D36: ='Data Sheet'!B93 -> 1207.08 | E36: ='Data Sheet'!C93 -> 1214.74 | F36: ='Data Sheet'!D93 -> 1220.43 | G36: ='Data Sheet'!E93 -> 1225.86 | H36: ='Data Sheet'!F93 -> 1229.22 | I36: ='Data Sheet'!G93 -> 1230.88 | J36: ='Data Sheet'!H93 -> 1232.33 | K36: ='Data Sheet'!I93 -> 1242.8 | ... M36: ='Data Sheet'!K93 -> 1251.41
B38: Earnings per Share | D38: =D33/D36 -> 6.6422689 | E38: =E33/E36 -> 7.1773384 | F38: =F33/F36 -> 7.5816475 | G38: =G33/G36 -> 8.7738078 | H38: =H33/H36 -> 10.718553 | I38: =I33/I36 -> 8.779028 | J38: =J33/J36 -> 11.030657 | K38: =K33/K36 -> 13.983811 | ... M38: =M33/M36 -> 13.790524
B39: EPS Growth | D39: NA | E39: =E38/D38-1 -> 0.080555217 | F39: =F38/E38-1 -> 0.056331341 | G39: =G38/F38-1 -> 0.15724291 | H39: =H38/G38-1 -> 0.22165353 | I39: =I38/H38-1 -> -0.18095028 | J39: =J38/I38-1 -> 0.25647821 | K39: =K38/J38-1 -> 0.26772234 | L39: =L38/K38-1 -> -0.0021455732 | M39: =M38/L38-1 -> -0.011701693
B41: Dividend per Share | D41: ='Data Sheet'!B31/'Historical Financial Statement'!D36 -> 5.6666667 | E41: ='Data Sheet'!C31/'Historical Financial Statement'!E36 -> 4.7500041 | F41: ='Data Sheet'!D31/'Historical Financial Statement'!F36 -> 5.1499963 | G41: ='Data Sheet'!E31/'Historical Financial Statement'!G36 -> 5.7500041 | H41: ='Data Sheet'!F31/'Historical Financial Statement'!H36 -> 10.149998 | I41: ='Data Sheet'!G31/'Historical Financial Statement'!I36 -> 10.75 | J41: ='Data Sheet'!H31/'Historical Financial Statement'!J36 -> 11.500004 | K41: ='Data Sheet'!I31/'Historical Financial Statement'!K36 -> 15.5 | ... M41: ='Data Sheet'!K31/'Historical Financial Statement'!M36 -> 14.349997
B42: Dividend Payout Ratio | D42: =D41/D38 -> 0.85312214 | E42: =E41/E38 -> 0.66180579 | F42: =F41/F38 -> 0.6792714 | G42: =G41/G38 -> 0.65536016 | H42: =H41/H38 -> 0.94695593 | I42: =I41/I38 -> 1.2245091 | J42: =J41/J38 -> 1.0425493 | K42: =K41/K38 -> 1.1084246 | ... M42: =M41/M38 -> 1.0405694
B44: Retained Earnings | D44: =IF(D38>D41,1-D42,0) -> 0.14687786 | E44: =IF(E38>E41,1-E42,0) -> 0.33819421 | F44: =IF(F38>F41,1-F42,0) -> 0.3207286 | G44: =IF(G38>G41,1-G42,0) -> 0.34463984 | H44: =IF(H38>H41,1-H42,0) -> 0.053044068 | I44: =IF(I38>I41,1-I42,0) -> 0 | J44: =IF(J38>J41,1-J42,0) -> 0 | K44: =IF(K38>K41,1-K42,0) -> 0 | ... M44: =IF(M38>M41,1-M42,0) -> 0
B46: ="Balancesheet - "&'Data Sheet'!B1 -> Balancesheet - ITC LTD
B47: Equity Share Capital | D47: ='Data Sheet'!B57 -> 804.72 | E47: ='Data Sheet'!C57 -> 1214.74 | F47: ='Data Sheet'!D57 -> 1220.43 | G47: ='Data Sheet'!E57 -> 1225.86 | H47: ='Data Sheet'!F57 -> 1229.22 | I47: ='Data Sheet'!G57 -> 1230.88 | J47: ='Data Sheet'!H57 -> 1232.33 | K47: ='Data Sheet'!I57 -> 1242.8 | ... M47: ='Data Sheet'!K57 -> 1251.41
B48: Reserves | D48: ='Data Sheet'!B58 -> 41874.8 | E48: ='Data Sheet'!C58 -> 45198.19 | F48: ='Data Sheet'!D58 -> 51289.68 | G48: ='Data Sheet'!E58 -> 57915.01 | H48: ='Data Sheet'!F58 -> 64044.04 | I48: ='Data Sheet'!G58 -> 59116.46 | J48: ='Data Sheet'!H58 -> 61223.24 | K48: ='Data Sheet'!I58 -> 67912.46 | ... M48: ='Data Sheet'!K58 -> 68778.64
B49: Borrowings | D49: ='Data Sheet'!B59 -> 83.78 | E49: ='Data Sheet'!C59 -> 45.72 | F49: ='Data Sheet'!D59 -> 35.92 | G49: ='Data Sheet'!E59 -> 13.44 | H49: ='Data Sheet'!F59 -> 277.45 | I49: ='Data Sheet'!G59 -> 270.83 | J49: ='Data Sheet'!H59 -> 249.44 | K49: ='Data Sheet'!I59 -> 306.04 | ... M49: ='Data Sheet'!K59 -> 284.54
B50: Other Liabilities | D50: ='Data Sheet'!B60 -> 8888.04 | E50: ='Data Sheet'!C60 -> 9439.67 | F50: ='Data Sheet'!D60 -> 11694.85 | G50: ='Data Sheet'!E60 -> 12584.73 | H50: ='Data Sheet'!F60 -> 11760.04 | I50: ='Data Sheet'!G60 -> 13142.59 | J50: ='Data Sheet'!H60 -> 14491.01 | K50: ='Data Sheet'!I60 -> 16369.66 | ... M50: ='Data Sheet'!K60 -> 17688.11
B51: Total Liabilities | D51: =SUM(D47:D50) -> 51651.34 | E51: =SUM(E47:E50) -> 55898.32 | F51: =SUM(F47:F50) -> 64240.88 | G51: =SUM(G47:G50) -> 71739.04 | H51: =SUM(H47:H50) -> 77310.75 | I51: =SUM(I47:I50) -> 73760.76 | J51: =SUM(J47:J50) -> 77196.02 | K51: =SUM(K47:K50) -> 85830.96 | ... M51: =SUM(M47:M50) -> 88002.7
B53: Net Block | D53: ='Data Sheet'!B62 -> 15106.63 | E53: ='Data Sheet'!C62 -> 15893.48 | F53: ='Data Sheet'!D62 -> 16523.96 | G53: ='Data Sheet'!E62 -> 19374.19 | H53: ='Data Sheet'!F62 -> 21713.34 | I53: ='Data Sheet'!G62 -> 23298.48 | J53: ='Data Sheet'!H62 -> 24231.59 | K53: ='Data Sheet'!I62 -> 25851.27 | ... M53: ='Data Sheet'!K62 -> 21954.85
B54: Capital Work in Progress | D54: ='Data Sheet'!B63 -> 2559.72 | E54: ='Data Sheet'!C63 -> 3729.89 | F54: ='Data Sheet'!D63 -> 5508.33 | G54: ='Data Sheet'!E63 -> 4136.42 | H54: ='Data Sheet'!F63 -> 3256.46 | I54: ='Data Sheet'!G63 -> 4011.29 | J54: ='Data Sheet'!H63 -> 3225.54 | K54: ='Data Sheet'!I63 -> 3003.3 | ... M54: ='Data Sheet'!K63 -> 1090.91
B55: Investments | D55: ='Data Sheet'!B64 -> 11747.59 | E55: ='Data Sheet'!C64 -> 17581.38 | F55: ='Data Sheet'!D64 -> 22052.86 | G55: ='Data Sheet'!E64 -> 25043.49 | H55: ='Data Sheet'!F64 -> 28663.35 | I55: ='Data Sheet'!G64 -> 24870.87 | J55: ='Data Sheet'!H64 -> 24841.01 | K55: ='Data Sheet'!I64 -> 29415.02 | ... M55: ='Data Sheet'!K64 -> 34719.82
B56: Other Assets | D56: ='Data Sheet'!B65-('Data Sheet'!B67+'Data Sheet'!B68+'Data Sheet'!B69) -> 5194.82 | E56: ='Data Sheet'!C65-('Data Sheet'!C67+'Data Sheet'!C68+'Data Sheet'!C69) -> 5135.78 | F56: ='Data Sheet'!D65-('Data Sheet'!D67+'Data Sheet'!D68+'Data Sheet'!D69) -> 7078.75 | G56: ='Data Sheet'!E65-('Data Sheet'!E67+'Data Sheet'!E68+'Data Sheet'!E69) -> 7138.07 | H56: ='Data Sheet'!F65-('Data Sheet'!F67+'Data Sheet'!F68+'Data Sheet'!F69) -> 4958.45 | I56: ='Data Sheet'!G65-('Data Sheet'!G67+'Data Sheet'!G68+'Data Sheet'!G69) -> 4022.24 | J56: ='Data Sheet'!H65-('Data Sheet'!H67+'Data Sheet'!H68+'Data Sheet'!H69) -> 6917.41 | K56: ='Data Sheet'!I65-('Data Sheet'!I67+'Data Sheet'!I68+'Data Sheet'!I69) -> 7953.85 | ... M56: ='Data Sheet'!K65-('Data Sheet'!K67+'Data Sheet'!K68+'Data Sheet'!K69) -> 5867.53
B57: Total Non Current Assets | D57: =SUM(D53:D56) -> 34608.76 | E57: =SUM(E53:E56) -> 42340.53 | F57: =SUM(F53:F56) -> 51163.9 | G57: =SUM(G53:G56) -> 55692.17 | H57: =SUM(H53:H56) -> 58591.6 | I57: =SUM(I53:I56) -> 56202.88 | J57: =SUM(J53:J56) -> 59215.55 | K57: =SUM(K53:K56) -> 66223.44 | ... M57: =SUM(M53:M56) -> 63633.11
...

Sheet Common Size Statement
B2: ="Commonsize Statement - "&'Data Sheet'!B1 -> Commonsize Statement - ITC LTD
B3: Years | D3: ='Data Sheet'!B16 -> 42460 | E3: ='Data Sheet'!C16 -> 42825 | F3: ='Data Sheet'!D16 -> 43190 | G3: ='Data Sheet'!E16 -> 43555 | H3: ='Data Sheet'!F16 -> 43921 | I3: ='Data Sheet'!G16 -> 44286 | J3: ='Data Sheet'!H16 -> 44651 | K3: ='Data Sheet'!I16 -> 45016 | ... M3: ='Data Sheet'!K16 -> 45747
B5: Income Statement
B7: Sales | D7: ='Data Sheet'!B17/'Data Sheet'!B17 -> 1 | E7: ='Data Sheet'!C17/'Data Sheet'!C17 -> 1 | F7: ='Data Sheet'!D17/'Data Sheet'!D17 -> 1 | G7: ='Data Sheet'!E17/'Data Sheet'!E17 -> 1 | H7: ='Data Sheet'!F17/'Data Sheet'!F17 -> 1 | I7: ='Data Sheet'!G17/'Data Sheet'!G17 -> 1 | J7: ='Data Sheet'!H17/'Data Sheet'!H17 -> 1 | K7: ='Data Sheet'!I17/'Data Sheet'!I17 -> 1 | ... M7: ='Data Sheet'!K17/'Data Sheet'!K17 -> 1
B8: Raw Material Cost | D8: ='Data Sheet'!B18/'Data Sheet'!B$17 -> 0.35119016 | E8: ='Data Sheet'!C18/'Data Sheet'!C$17 -> 0.36140887 | F8: ='Data Sheet'!D18/'Data Sheet'!D$17 -> 0.3412677 | G8: ='Data Sheet'!E18/'Data Sheet'!E$17 -> 0.36457743 | H8: ='Data Sheet'!F18/'Data Sheet'!F$17 -> 0.36544727 | I8: ='Data Sheet'!G18/'Data Sheet'!G$17 -> 0.42179833 | J8: ='Data Sheet'!H18/'Data Sheet'!H$17 -> 0.44638924 | K8: ='Data Sheet'!I18/'Data Sheet'!I$17 -> 0.41405473 | ... M8: ='Data Sheet'!K18/'Data Sheet'!K$17 -> 0.4341864
B9: Change in Inventory | D9: ='Data Sheet'!B19/'Data Sheet'!B$17 -> 0.0049851883 | E9: ='Data Sheet'!C19/'Data Sheet'!C$17 -> -0.013855582 | F9: ='Data Sheet'!D19/'Data Sheet'!D$17 -> -0.023654432 | G9: ='Data Sheet'!E19/'Data Sheet'!E$17 -> 0.0042033878 | H9: ='Data Sheet'!F19/'Data Sheet'!F$17 -> 0.014236946 | I9: ='Data Sheet'!G19/'Data Sheet'!G$17 -> 0.013099947 | J9: ='Data Sheet'!H19/'Data Sheet'!H$17 -> 0.011311818 | K9: ='Data Sheet'!I19/'Data Sheet'!I$17 -> 0.0050563297 | ... M9: ='Data Sheet'!K19/'Data Sheet'!K$17 -> 0.0096338001
B10: Power and Fuel | D10: ='Data Sheet'!B20/'Data Sheet'!B$17 -> 0.014591716 | E10: ='Data Sheet'!C20/'Data Sheet'!C$17 -> 0.013662913 | F10: ='Data Sheet'!D20/'Data Sheet'!D$17 -> 0.015040643 | G10: ='Data Sheet'!E20/'Data Sheet'!E$17 -> 0.01544759 | H10: ='Data Sheet'!F20/'Data Sheet'!F$17 -> 0.015810617 | I10: ='Data Sheet'!G20/'Data Sheet'!G$17 -> 0.014202116 | J10: ='Data Sheet'!H20/'Data Sheet'!H$17 -> 0.01467189 | K10: ='Data Sheet'!I20/'Data Sheet'!I$17 -> 0.017376718 | ... M10: ='Data Sheet'!K20/'Data Sheet'!K$17 -> 0.012948842
B11: Other Mfr. Exp | D11: ='Data Sheet'!B21/'Data Sheet'!B$17 -> 0.040354816 | E11: ='Data Sheet'!C21/'Data Sheet'!C$17 -> 0.039373264 | F11: ='Data Sheet'!D21/'Data Sheet'!D$17 -> 0.039071609 | G11: ='Data Sheet'!E21/'Data Sheet'!E$17 -> 0.038705549 | H11: ='Data Sheet'!F21/'Data Sheet'!F$17 -> 0.038638973 | I11: ='Data Sheet'!G21/'Data Sheet'!G$17 -> 0.032222131 | J11: ='Data Sheet'!H21/'Data Sheet'!H$17 -> 0.031126792 | K11: ='Data Sheet'!I21/'Data Sheet'!I$17 -> 0.032823348 | ... M11: ='Data Sheet'!K21/'Data Sheet'!K$17 -> 0.031137228
B12: Employee Cost | D12: ='Data Sheet'!B22/'Data Sheet'!B$17 -> 0.087797541 | E12: ='Data Sheet'!C22/'Data Sheet'!C$17 -> 0.084917788 | F12: ='Data Sheet'!D22/'Data Sheet'!D$17 -> 0.086559074 | G12: ='Data Sheet'!E22/'Data Sheet'!E$17 -> 0.086427727 | H12: ='Data Sheet'!F22/'Data Sheet'!F$17 -> 0.086980969 | I12: ='Data Sheet'!G22/'Data Sheet'!G$17 -> 0.090612283 | J12: ='Data Sheet'!H22/'Data Sheet'!H$17 -> 0.080642874 | K12: ='Data Sheet'!I22/'Data Sheet'!I$17 -> 0.080884073 | ... M12: ='Data Sheet'!K22/'Data Sheet'!K$17 -> 0.0819106
B13: Selling and admin | D13: ='Data Sheet'!B23/'Data Sheet'!B$17 -> 0.10874079 | E13: ='Data Sheet'!C23/'Data Sheet'!C$17 -> 0.09773146 | F13: ='Data Sheet'!D23/'Data Sheet'!D$17 -> 0.091023394 | G13: ='Data Sheet'!E23/'Data Sheet'!E$17 -> 0.094051086 | H13: ='Data Sheet'!F23/'Data Sheet'!F$17 -> 0.090885585 | I13: ='Data Sheet'!G23/'Data Sheet'!G$17 -> 0.086012776 | J13: ='Data Sheet'!H23/'Data Sheet'!H$17 -> 0.080112406 | K13: ='Data Sheet'!I23/'Data Sheet'!I$17 -> 0.079020821 | ... M13: ='Data Sheet'!K23/'Data Sheet'!K$17 -> 0.076912282
B14: Other Expenses | D14: ='Data Sheet'!B24/'Data Sheet'!B$17 -> 0.031534161 | E14: ='Data Sheet'!C24/'Data Sheet'!C$17 -> 0.027339154 | F14: ='Data Sheet'!D24/'Data Sheet'!D$17 -> 0.023153154 | G14: ='Data Sheet'!E24/'Data Sheet'!E$17 -> 0.021511358 | H14: ='Data Sheet'!F24/'Data Sheet'!F$17 -> 0.024806379 | I14: ='Data Sheet'!G24/'Data Sheet'!G$17 -> 0.021811726 | J14: ='Data Sheet'!H24/'Data Sheet'!H$17 -> 0.018302555 | K14: ='Data Sheet'!I24/'Data Sheet'!I$17 -> 0.018451465 | ... M14: ='Data Sheet'!K24/'Data Sheet'!K$17 -> 0.02949139
B15: Other Income | D15: ='Data Sheet'!B25/'Data Sheet'!B$17 -> 0.037842065 | E15: ='Data Sheet'!C25/'Data Sheet'!C$17 -> 0.041120615 | F15: ='Data Sheet'!D25/'Data Sheet'!D$17 -> 0.051550395 | G15: ='Data Sheet'!E25/'Data Sheet'!E$17 -> 0.043038024 | H15: ='Data Sheet'!F25/'Data Sheet'!F$17 -> 0.04894579 | I15: ='Data Sheet'!G25/'Data Sheet'!G$17 -> 0.052315944 | J15: ='Data Sheet'!H25/'Data Sheet'!H$17 -> 0.031490386 | K15: ='Data Sheet'!I25/'Data Sheet'!I$17 -> 0.029577957 | ... M15: ='Data Sheet'!K25/'Data Sheet'!K$17 -> 0.23624656
B16: Depreciation | D16: ='Data Sheet'!B26/'Data Sheet'!B$17 -> 0.027490234 | E16: ='Data Sheet'!C26/'Data Sheet'!C$17 -> 0.026954751 | F16: ='Data Sheet'!D26/'Data Sheet'!D$17 -> 0.028453629 | G16: ='Data Sheet'!E26/'Data Sheet'!E$17 -> 0.028891645 | H16: ='Data Sheet'!F26/'Data Sheet'!F$17 -> 0.033306066 | I16: ='Data Sheet'!G26/'Data Sheet'!G$17 -> 0.033407941 | J16: ='Data Sheet'!H26/'Data Sheet'!H$17 -> 0.028566628 | K16: ='Data Sheet'!I26/'Data Sheet'!I$17 -> 0.025508104 | ... M16: ='Data Sheet'!K26/'Data Sheet'!K$17 -> 0.021856705
B17: Interest | D17: ='Data Sheet'!B27/'Data Sheet'!B$17 -> 0.001993514 | E17: ='Data Sheet'!C27/'Data Sheet'!C$17 -> 0.0011464286 | F17: ='Data Sheet'!D27/'Data Sheet'!D$17 -> 0.0026470151 | G17: ='Data Sheet'!E27/'Data Sheet'!E$17 -> 0.0014770505 | H17: ='Data Sheet'!F27/'Data Sheet'!F$17 -> 0.0016477787 | I17: ='Data Sheet'!G27/'Data Sheet'!G$17 -> 0.0011768778 | J17: ='Data Sheet'!H27/'Data Sheet'!H$17 -> 0.00098920694 | K17: ='Data Sheet'!I27/'Data Sheet'!I$17 -> 0.0010966027 | ... M17: ='Data Sheet'!K27/'Data Sheet'!K$17 -> 0.00059822095
B18: Profit before tax | D18: ='Data Sheet'!B28/'Data Sheet'!B$17 -> 0.37913432 | E18: ='Data Sheet'!C28/'Data Sheet'!C$17 -> 0.3747304 | F18: ='Data Sheet'!D28/'Data Sheet'!D$17 -> 0.40067974 | G18: ='Data Sheet'!E28/'Data Sheet'!E$17 -> 0.39615197 | H18: ='Data Sheet'!F28/'Data Sheet'!F$17 -> 0.4056591 | I18: ='Data Sheet'!G28/'Data Sheet'!G$17 -> 0.36417171 | J18: ='Data Sheet'!H28/'Data Sheet'!H$17 -> 0.34200062 | K18: ='Data Sheet'!I28/'Data Sheet'!I$17 -> 0.36541842 | ... M18: ='Data Sheet'!K28/'Data Sheet'!K$17 -> 0.55683869
B19: Tax | D19: ='Data Sheet'!B29/'Data Sheet'!B$17 -> 0.13671658 | E19: ='Data Sheet'!C29/'Data Sheet'!C$17 -> 0.12974986 | F19: ='Data Sheet'!D29/'Data Sheet'!D$17 -> 0.13616972 | G19: ='Data Sheet'!E29/'Data Sheet'!E$17 -> 0.13061595 | H19: ='Data Sheet'!F29/'Data Sheet'!F$17 -> 0.089937171 | I19: ='Data Sheet'!G29/'Data Sheet'!G$17 -> 0.092479209 | J19: ='Data Sheet'!H29/'Data Sheet'!H$17 -> 0.086361278 | K19: ='Data Sheet'!I29/'Data Sheet'!I$17 -> 0.090785224 | ... M19: ='Data Sheet'!K29/'Data Sheet'!K$17 -> 0.091478551
B20: Net profit | D20: ='Data Sheet'!B30/'Data Sheet'!B$17 -> 0.23842688 | E20: ='Data Sheet'!C30/'Data Sheet'!C$17 -> 0.24058961 | F20: ='Data Sheet'!D30/'Data Sheet'!D$17 -> 0.25941254 | G20: ='Data Sheet'!E30/'Data Sheet'!E$17 -> 0.2604973 | H20: ='Data Sheet'!F30/'Data Sheet'!F$17 -> 0.30991988 | I20: ='Data Sheet'!G30/'Data Sheet'!G$17 -> 0.26719187 | J20: ='Data Sheet'!H30/'Data Sheet'!H$17 -> 0.25134431 | K20: ='Data Sheet'!I30/'Data Sheet'!I$17 -> 0.27061368 | ... M20: ='Data Sheet'!K30/'Data Sheet'!K$17 -> 0.46129964
B23: Balance Sheet
B25: Total Liabilities | D25: ='Data Sheet'!B61/'Data Sheet'!B61 -> 1 | E25: ='Data Sheet'!C61/'Data Sheet'!C61 -> 1 | F25: ='Data Sheet'!D61/'Data Sheet'!D61 -> 1 | G25: ='Data Sheet'!E61/'Data Sheet'!E61 -> 1 | H25: ='Data Sheet'!F61/'Data Sheet'!F61 -> 1 | I25: ='Data Sheet'!G61/'Data Sheet'!G61 -> 1 | J25: ='Data Sheet'!H61/'Data Sheet'!H61 -> 1 | K25: ='Data Sheet'!I61/'Data Sheet'!I61 -> 1 | ... M25: ='Data Sheet'!K61/'Data Sheet'!K61 -> 1
B26: Equity Share Capital | D26: ='Data Sheet'!B57/'Historical Financial Statement'!D$51 -> 0.015579847 | E26: ='Data Sheet'!C57/'Historical Financial Statement'!E$51 -> 0.021731243 | F26: ='Data Sheet'!D57/'Historical Financial Statement'!F$51 -> 0.018997716 | G26: ='Data Sheet'!E57/'Historical Financial Statement'!G$51 -> 0.017087767 | H26: ='Data Sheet'!F57/'Historical Financial Statement'!H$51 -> 0.015899729 | I26: ='Data Sheet'!G57/'Historical Financial Statement'!I$51 -> 0.016687464 | J26: ='Data Sheet'!H57/'Historical Financial Statement'!J$51 -> 0.015963647 | K26: ='Data Sheet'!I57/'Historical Financial Statement'!K$51 -> 0.014479624 | ... M26: ='Data Sheet'!K57/'Historical Financial Statement'!M$51 -> 0.014220132
B27: Reserves | D27: ='Data Sheet'!B58/'Historical Financial Statement'!D$51 -> 0.8107205 | E27: ='Data Sheet'!C58/'Historical Financial Statement'!E$51 -> 0.80857868 | F27: ='Data Sheet'!D58/'Historical Financial Statement'!F$51 -> 0.79839629 | G27: ='Data Sheet'!E58/'Historical Financial Statement'!G$51 -> 0.80730116 | H27: ='Data Sheet'!F58/'Historical Financial Statement'!H$51 -> 0.8283976 | I27: ='Data Sheet'!G58/'Historical Financial Statement'!I$51 -> 0.80146219 | J27: ='Data Sheet'!H58/'Historical Financial Statement'!J$51 -> 0.79308804 | K27: ='Data Sheet'!I58/'Historical Financial Statement'!K$51 -> 0.791235 | ... M27: ='Data Sheet'!K58/'Historical Financial Statement'!M$51 -> 0.78155148
B28: Borrowings | D28: ='Data Sheet'!B59/'Historical Financial Statement'!D$51 -> 0.0016220296 | E28: ='Data Sheet'!C59/'Historical Financial Statement'!E$51 -> 0.00081791367 | F28: ='Data Sheet'!D59/'Historical Financial Statement'!F$51 -> 0.00055914552 | G28: ='Data Sheet'!E59/'Historical Financial Statement'!G$51 -> 0.00018734569 | H28: ='Data Sheet'!F59/'Historical Financial Statement'!H$51 -> 0.0035887635 | I28: ='Data Sheet'!G59/'Historical Financial Statement'!I$51 -> 0.0036717355 | J28: ='Data Sheet'!H59/'Historical Financial Statement'!J$51 -> 0.0032312547 | K28: ='Data Sheet'!I59/'Historical Financial Statement'!K$51 -> 0.0035656132 | ... M28: ='Data Sheet'!K59/'Historical Financial Statement'!M$51 -> 0.0032333099
B29: Other Liabilities | D29: ='Data Sheet'!B60/'Historical Financial Statement'!D$51 -> 0.17207763 | E29: ='Data Sheet'!C60/'Historical Financial Statement'!E$51 -> 0.16887216 | F29: ='Data Sheet'!D60/'Historical Financial Statement'!F$51 -> 0.18204685 | G29: ='Data Sheet'!E60/'Historical Financial Statement'!G$51 -> 0.17542373 | H29: ='Data Sheet'!F60/'Historical Financial Statement'!H$51 -> 0.1521139 | I29: ='Data Sheet'!G60/'Historical Financial Statement'!I$51 -> 0.17817861 | J29: ='Data Sheet'!H60/'Historical Financial Statement'!J$51 -> 0.18771706 | K29: ='Data Sheet'!I60/'Historical Financial Statement'!K$51 -> 0.19071976 | ... M29: ='Data Sheet'!K60/'Historical Financial Statement'!M$51 -> 0.20099508
B31: Total Assets | D31: ='Historical Financial Statement'!D64/'Historical Financial Statement'!D$64 -> 1 | E31: ='Historical Financial Statement'!E64/'Historical Financial Statement'!E$64 -> 1 | F31: ='Historical Financial Statement'!F64/'Historical Financial Statement'!F$64 -> 1 | G31: ='Historical Financial Statement'!G64/'Historical Financial Statement'!G$64 -> 1 | H31: ='Historical Financial Statement'!H64/'Historical Financial Statement'!H$64 -> 1 | I31: ='Historical Financial Statement'!I64/'Historical Financial Statement'!I$64 -> 1 | J31: ='Historical Financial Statement'!J64/'Historical Financial Statement'!J$64 -> 1 | K31: ='Historical Financial Statement'!K64/'Historical Financial Statement'!K$64 -> 1 | ... M31: ='Historical Financial Statement'!M64/'Historical Financial Statement'!M$64 -> 1
B32: Net Block | D32: ='Data Sheet'!B62/'Historical Financial Statement'!D$64 -> 0.29247315 | E32: ='Data Sheet'!C62/'Historical Financial Statement'!E$64 -> 0.2843284 | F32: ='Data Sheet'!D62/'Historical Financial Statement'!F$64 -> 0.25721877 | G32: ='Data Sheet'!E62/'Historical Financial Statement'!G$64 -> 0.27006481 | H32: ='Data Sheet'!F62/'Historical Financial Statement'!H$64 -> 0.28085797 | I32: ='Data Sheet'!G62/'Historical Financial Statement'!I$64 -> 0.31586551 | J32: ='Data Sheet'!H62/'Historical Financial Statement'!J$64 -> 0.31389688 | K32: ='Data Sheet'!I62/'Historical Financial Statement'!K$64 -> 0.30118817 | ... M32: ='Data Sheet'!K62/'Historical Financial Statement'!M$64 -> 0.24947928
B33: Capital Work in Progress | D33: ='Data Sheet'!B63/'Historical Financial Statement'!D$64 -> 0.049557669 | E33: ='Data Sheet'!C63/'Historical Financial Statement'!E$64 -> 0.066726335 | F33: ='Data Sheet'!D63/'Historical Financial Statement'!F$64 -> 0.085744934 | G33: ='Data Sheet'!E63/'Historical Financial Statement'!G$64 -> 0.057659261 | H33: ='Data Sheet'!F63/'Historical Financial Statement'!H$64 -> 0.042121697 | I33: ='Data Sheet'!G63/'Historical Financial Statement'!I$64 -> 0.054382439 | J33: ='Data Sheet'!H63/'Historical Financial Statement'!J$64 -> 0.04178376 | K33: ='Data Sheet'!I63/'Historical Financial Statement'!K$64 -> 0.03499087 | ... M33: ='Data Sheet'!K63/'Historical Financial Statement'!M$64 -> 0.012396324
B34: Investments | D34: ='Data Sheet'!B64/'Historical Financial Statement'!D$64 -> 0.22744018 | E34: ='Data Sheet'!C64/'Historical Financial Statement'!E$64 -> 0.3145243 | F34: ='Data Sheet'!D64/'Historical Financial Statement'!F$64 -> 0.3432839 | G34: ='Data Sheet'!E64/'Historical Financial Statement'!G$64 -> 0.34909151 | H34: ='Data Sheet'!F64/'Historical Financial Statement'!H$64 -> 0.37075504 | I34: ='Data Sheet'!G64/'Historical Financial Statement'!I$64 -> 0.33718294 | J34: ='Data Sheet'!H64/'Historical Financial Statement'!J$64 -> 0.32179133 | K34: ='Data Sheet'!I64/'Historical Financial Statement'!K$64 -> 0.34270874 | ... M34: ='Data Sheet'!K64/'Historical Financial Statement'!M$64 -> 0.3945313
B35: Other Assets | D35: ='Historical Financial Statement'!D56/'Historical Financial Statement'!D$64 -> 0.10057474 | E35: ='Historical Financial Statement'!E56/'Historical Financial Statement'!E$64 -> 0.09187718 | F35: ='Historical Financial Statement'!F56/'Historical Financial Statement'!F$64 -> 0.11019074 | G35: ='Historical Financial Statement'!G56/'Historical Financial Statement'!G$64 -> 0.099500495 | H35: ='Historical Financial Statement'!H56/'Historical Financial Statement'!H$64 -> 0.064136617 | I35: ='Historical Financial Statement'!I56/'Historical Financial Statement'!I$64 -> 0.054530891 | J35: ='Historical Financial Statement'!J56/'Historical Financial Statement'!J$64 -> 0.089608376 | K35: ='Historical Financial Statement'!K56/'Historical Financial Statement'!K$64 -> 0.092668776 | ... M35: ='Historical Financial Statement'!M56/'Historical Financial Statement'!M$64 -> 0.066674432
B36: Receivables | D36: ='Data Sheet'!B67/'Historical Financial Statement'!D$64 -> 0.03711772 | E36: ='Data Sheet'!C67/'Historical Financial Statement'!E$64 -> 0.044264121 | F36: ='Data Sheet'!D67/'Historical Financial Statement'!F$64 -> 0.041753631 | G36: ='Data Sheet'!E67/'Historical Financial Statement'!G$64 -> 0.056249428 | H36: ='Data Sheet'!F67/'Historical Financial Statement'!H$64 -> 0.033145196 | I36: ='Data Sheet'!G67/'Historical Financial Statement'!I$64 -> 0.033916408 | J36: ='Data Sheet'!H67/'Historical Financial Statement'!J$64 -> 0.031891541 | K36: ='Data Sheet'!I67/'Historical Financial Statement'!K$64 -> 0.034441768 | ... M36: ='Data Sheet'!K67/'Historical Financial Statement'!M$64 -> 0.053630968
B37: Inventory | D37: ='Data Sheet'!B68/'Historical Financial Statement'!D$64 -> 0.17544753 | E37: ='Data Sheet'!C68/'Historical Financial Statement'!E$64 -> 0.14519399 | F37: ='Data Sheet'!D68/'Historical Financial Statement'!F$64 -> 0.11667166 | G37: ='Data Sheet'!E68/'Historical Financial Statement'!G$64 -> 0.10955764 | H37: ='Data Sheet'!F68/'Historical Financial Statement'!H$64 -> 0.11485246 | I37: ='Data Sheet'!G68/'Historical Financial Statement'!I$64 -> 0.14095788 | J37: ='Data Sheet'!H68/'Historical Financial Statement'!J$64 -> 0.14073459 | K37: ='Data Sheet'!I68/'Historical Financial Statement'!K$64 -> 0.13714352 | ... M37: ='Data Sheet'!K68/'Historical Financial Statement'!M$64 -> 0.17769409
B38: Cash & Bank | D38: ='Data Sheet'!B69/'Historical Financial Statement'!D$64 -> 0.11738902 | E38: ='Data Sheet'!C69/'Historical Financial Statement'!E$64 -> 0.053085674 | F38: ='Data Sheet'!D69/'Historical Financial Statement'!F$64 -> 0.045136368 | G38: ='Data Sheet'!E69/'Historical Financial Statement'!G$64 -> 0.057876855 | H38: ='Data Sheet'!F69/'Historical Financial Statement'!H$64 -> 0.094131023 | I38: ='Data Sheet'!G69/'Historical Financial Statement'!I$64 -> 0.063163937 | J38: ='Data Sheet'!H69/'Historical Financial Statement'!J$64 -> 0.060293523 | K38: ='Data Sheet'!I69/'Historical Financial Statement'!K$64 -> 0.056858155 | ... M38: ='Data Sheet'!K69/'Historical Financial Statement'!M$64 -> 0.045593601

Sheet Ratio Analysis
B2: ="Ratio Analysis - "&'Data Sheet'!B1 -> Ratio Analysis - ITC LTD
B3: Particulars | D3: ='Data Sheet'!B16 -> 42460 | E3: ='Data Sheet'!C16 -> 42825 | F3: ='Data Sheet'!D16 -> 43190 | G3: ='Data Sheet'!E16 -> 43555 | H3: ='Data Sheet'!F16 -> 43921 | I3: ='Data Sheet'!G16 -> 44286 | J3: ='Data Sheet'!H16 -> 44651 | K3: ='Data Sheet'!I16 -> 45016 | ... M3: ='Data Sheet'!K16 -> 45747 | N3: Trend | O3: Mean | P3: Median
B5: Sales Growth | D5: NA | E5: ='Data Sheet'!C17/'Data Sheet'!B17-1 -> 0.09123012 | F5: ='Data Sheet'!D17/'Data Sheet'!C17-1 -> 0.015931219 | G5: ='Data Sheet'!E17/'Data Sheet'!D17-1 -> 0.11256063 | H5: ='Data Sheet'!F17/'Data Sheet'!E17-1 -> 0.021682439 | I5: ='Data Sheet'!G17/'Data Sheet'!F17-1 -> -0.0026372963 | J5: ='Data Sheet'!H17/'Data Sheet'!G17-1 -> 0.23117498 | K5: ='Data Sheet'!I17/'Data Sheet'!H17-1 -> 0.16942152 | L5: ='Data Sheet'!J17/'Data Sheet'!I17-1 -> -0.042119724 | M5: ='Data Sheet'!K17/'Data Sheet'!J17-1 -> 0.10880596 | O5: =AVERAGE(D5:M5) -> 0.078449983 | P5: =MEDIAN(D5:M5) -> 0.09123012
B6: EBITDA Growth | D6: NA | E6: ='Historical Financial Statement'!E18/'Historical Financial Statement'!D18-1 -> 0.064550848 | F6: ='Historical Financial Statement'!F18/'Historical Financial Statement'!E18-1 -> 0.067945268 | G6: ='Historical Financial Statement'!G18/'Historical Financial Statement'!F18-1 -> 0.12207796 | H6: ='Historical Financial Statement'!H18/'Historical Financial Statement'!G18-1 -> 0.043487783 | I6: ='Historical Financial Statement'!I18/'Historical Financial Statement'!H18-1 -> -0.1178047 | J6: ='Historical Financial Statement'!J18/'Historical Financial Statement'!I18-1 -> 0.20852129 | K6: ='Historical Financial Statement'!K18/'Historical Financial Statement'!J18-1 -> 0.24637895 | L6: ='Historical Financial Statement'!L18/'Historical Financial Statement'!K18-1 -> -0.020102893 | M6: ='Historical Financial Statement'!M18/'Historical Financial Statement'!L18-1 -> 0.025882649 | O6: =AVERAGE(D6:M6) -> 0.07121524 | P6: =MEDIAN(D6:M6) -> 0.064550848
B7: EBT Growth | D7: NA | E7: ='Historical Financial Statement'!E27/'Historical Financial Statement'!D27-1 -> 0.066666617 | F7: ='Historical Financial Statement'!F27/'Historical Financial Statement'!E27-1 -> 0.06319243 | G7: ='Historical Financial Statement'!G27/'Historical Financial Statement'!F27-1 -> 0.12525825 | H7: ='Historical Financial Statement'!H27/'Historical Financial Statement'!G27-1 -> 0.032096655 | I7: ='Historical Financial Statement'!I27/'Historical Financial Statement'!H27-1 -> -0.12805801 | J7: ='Historical Financial Statement'!J27/'Historical Financial Statement'!I27-1 -> 0.22586292 | K7: ='Historical Financial Statement'!K27/'Historical Financial Statement'!J27-1 -> 0.26481845 | L7: ='Historical Financial Statement'!L27/'Historical Financial Statement'!K27-1 -> -0.0078559948 | M7: ='Historical Financial Statement'!M27/'Historical Financial Statement'!L27-1 -> 0.021908248 | O7: =AVERAGE(D7:M7) -> 0.073765507 | P7: =MEDIAN(D7:M7) -> 0.06319243
B8: Dividend Growth | D8: NA | E8: ='Data Sheet'!C31/'Data Sheet'!B31-1 -> -0.15644462 | F8: ='Data Sheet'!D31/'Data Sheet'!C31-1 -> 0.089287385 | G8: ='Data Sheet'!E31/'Data Sheet'!D31-1 -> 0.12147406 | H8: ='Data Sheet'!F31/'Data Sheet'!E31-1 -> 0.77005405 | I8: ='Data Sheet'!G31/'Data Sheet'!F31-1 -> 0.060543835 | J8: ='Data Sheet'!H31/'Data Sheet'!G31-1 -> 0.071028026 | K8: ='Data Sheet'!I31/'Data Sheet'!H31-1 -> 0.35927687 | L8: ='Data Sheet'!J31/'Data Sheet'!I31-1 -> -0.10885617 | M8: ='Data Sheet'!K31/'Data Sheet'!J31-1 -> 0.046093953 | O8: =AVERAGE(D8:M8) -> 0.13916193 | P8: =MEDIAN(D8:M8) -> 0.071028026
B9: Net Profit Growth | D9: NA | E9: ='Historical Financial Statement'!E33/'Historical Financial Statement'!D33-1 -> 0.087412304 | F9: ='Historical Financial Statement'!F33/'Historical Financial Statement'!E33-1 -> 0.061279334 | G9: ='Historical Financial Statement'!G33/'Historical Financial Statement'!F33-1 -> 0.16239178 | H9: ='Historical Financial Statement'!H33/'Historical Financial Statement'!G33-1 -> 0.225002 | I9: ='Historical Financial Statement'!I33/'Historical Financial Statement'!H33-1 -> -0.1798442 | J9: ='Historical Financial Statement'!J33/'Historical Financial Statement'!I33-1 -> 0.25795836 | K9: ='Historical Financial Statement'!K33/'Historical Financial Statement'!J33-1 -> 0.27849303 | L9: ='Historical Financial Statement'!L33/'Historical Financial Statement'!K33-1 -> 0.0024069168 | M9: ='Historical Financial Statement'!M33/'Historical Financial Statement'!L33-1 -> -0.0093743668 | O9: =AVERAGE(D9:M9) -> 0.098413907 | P9: =MEDIAN(D9:M9) -> 0.087412304
B11: Gross Profit Margin | D11: ='Historical Financial Statement'!D12/'Historical Financial Statement'!D6 -> 0.51105095 | E11: ='Historical Financial Statement'!E12/'Historical Financial Statement'!E6 -> 0.48678158 | F11: ='Historical Financial Statement'!F12/'Historical Financial Statement'!F6 -> 0.49440654 | G11: ='Historical Financial Statement'!G12/'Historical Financial Statement'!G6 -> 0.49904509 | H11: ='Historical Financial Statement'!H12/'Historical Financial Statement'!H6 -> 0.50735912 | I11: ='Historical Financial Statement'!I12/'Historical Financial Statement'!I6 -> 0.45426509 | J11: ='Historical Financial Statement'!J12/'Historical Financial Statement'!J6 -> 0.43848102 | K11: ='Historical Financial Statement'!K12/'Historical Financial Statement'!K6 -> 0.45991746 | ... M11: ='Historical Financial Statement'!M12/'Historical Financial Statement'!M6 -> 0.44945073 | O11: =AVERAGE(D11:M11) -> 0.47757322 | P11: =MEDIAN(D11:M11) -> 0.48087812
B12: EBITDA Margin | D12: ='Historical Financial Statement'!D18/'Historical Financial Statement'!D6 -> 0.370776 | E12: ='Historical Financial Statement'!E18/'Historical Financial Statement'!E6 -> 0.36171097 | F12: ='Historical Financial Statement'!F18/'Historical Financial Statement'!F6 -> 0.38022999 | G12: ='Historical Financial Statement'!G18/'Historical Financial Statement'!G6 -> 0.38348265 | H12: ='Historical Financial Statement'!H18/'Historical Financial Statement'!H6 -> 0.39166716 | I12: ='Historical Financial Statement'!I18/'Historical Financial Statement'!I6 -> 0.34644059 | J12: ='Historical Financial Statement'!J18/'Historical Financial Statement'!J6 -> 0.34006606 | K12: ='Historical Financial Statement'!K18/'Historical Financial Statement'!K6 -> 0.36244517 | ... M12: ='Historical Financial Statement'!M18/'Historical Financial Statement'!M6 -> 0.34304706 | O12: =AVERAGE(D12:M12) -> 0.36506416 | P12: =MEDIAN(D12:M12) -> 0.36661056
B13: EBIT Margin | D13: =('Historical Financial Statement'!D18-'Historical Financial Statement'!D24)/'Historical Financial Statement'!D6 -> 0.34328576 | E13: =('Historical Financial Statement'!E18-'Historical Financial Statement'!E24)/'Historical Financial Statement'!E6 -> 0.33475622 | F13: =('Historical Financial Statement'!F18-'Historical Financial Statement'!F24)/'Historical Financial Statement'!F6 -> 0.35177636 | G13: =('Historical Financial Statement'!G18-'Historical Financial Statement'!G24)/'Historical Financial Statement'!G6 -> 0.354591 | H13: =('Historical Financial Statement'!H18-'Historical Financial Statement'!H24)/'Historical Financial Statement'!H6 -> 0.35836109 | I13: =('Historical Financial Statement'!I18-'Historical Financial Statement'!I24)/'Historical Financial Statement'!I6 -> 0.31303265 | J13: =('Historical Financial Statement'!J18-'Historical Financial Statement'!J24)/'Historical Financial Statement'!J6 -> 0.31149944 | K13: =('Historical Financial Statement'!K18-'Historical Financial Statement'!K24)/'Historical Financial Statement'!K6 -> 0.33693707 | ... M13: =('Historical Financial Statement'!M18-'Historical Financial Statement'!M24)/'Historical Financial Statement'!M6 -> 0.32119035 | O13: =AVERAGE(D13:M13) -> 0.33738593 | P13: =MEDIAN(D13:M13) -> 0.34011142
B14: EBT Margin | D14: ='Historical Financial Statement'!D27/'Historical Financial Statement'!D6 -> 0.34129225 | E14: ='Historical Financial Statement'!E27/'Historical Financial Statement'!E6 -> 0.33360979 | F14: ='Historical Financial Statement'!F27/'Historical Financial Statement'!F6 -> 0.34912935 | G14: ='Historical Financial Statement'!G27/'Historical Financial Statement'!G6 -> 0.35311395 | H14: ='Historical Financial Statement'!H27/'Historical Financial Statement'!H6 -> 0.35671331 | I14: ='Historical Financial Statement'!I27/'Historical Financial Statement'!I6 -> 0.31185577 | J14: ='Historical Financial Statement'!J27/'Historical Financial Statement'!J6 -> 0.31051023 | K14: ='Historical Financial Statement'!K27/'Historical Financial Statement'!K6 -> 0.33584046 | ... M14: ='Historical Financial Statement'!M27/'Historical Financial Statement'!M6 -> 0.32059213 | O14: =AVERAGE(D14:M14) -> 0.33605108 | P14: =MEDIAN(D14:M14) -> 0.33856636
B15: Net Profit Margin | D15: ='Historical Financial Statement'!D33/'Historical Financial Statement'!D6 -> 0.20457567 | E15: ='Historical Financial Statement'!E33/'Historical Financial Statement'!E6 -> 0.20385993 | F15: ='Historical Financial Statement'!F33/'Historical Financial Statement'!F6 -> 0.21295963 | G15: ='Historical Financial Statement'!G33/'Historical Financial Statement'!G6 -> 0.222498 | H15: ='Historical Financial Statement'!H33/'Historical Financial Statement'!H6 -> 0.26677614 | I15: ='Historical Financial Statement'!I33/'Historical Financial Statement'!I6 -> 0.21937656 | J15: ='Historical Financial Statement'!J33/'Historical Financial Statement'!J6 -> 0.22414895 | K15: ='Historical Financial Statement'!K33/'Historical Financial Statement'!K6 -> 0.24505524 | ... M15: ='Historical Financial Statement'!M33/'Historical Financial Statement'!M6 -> 0.22911358 | O15: =AVERAGE(D15:M15) -> 0.22848102 | P15: =MEDIAN(D15:M15) -> 0.22332348
B17: SalesExpenses%Sales | D17: ='Historical Financial Statement'!D15/'Historical Financial Statement'!D6 -> 0.14027495 | E17: ='Historical Financial Statement'!E15/'Historical Financial Statement'!E6 -> 0.12507061 | F17: ='Historical Financial Statement'!F15/'Historical Financial Statement'!F6 -> 0.11417655 | G17: ='Historical Financial Statement'!G15/'Historical Financial Statement'!G6 -> 0.11556244 | H17: ='Historical Financial Statement'!H15/'Historical Financial Statement'!H6 -> 0.11569196 | I17: ='Historical Financial Statement'!I15/'Historical Financial Statement'!I6 -> 0.1078245 | J17: ='Historical Financial Statement'!J15/'Historical Financial Statement'!J6 -> 0.09841496 | K17: ='Historical Financial Statement'!K15/'Historical Financial Statement'!K6 -> 0.097472286 | ... M17: ='Historical Financial Statement'!M15/'Historical Financial Statement'!M6 -> 0.10640367 | O17: =AVERAGE(D17:M17) -> 0.11250906 | P17: =MEDIAN(D17:M17) -> 0.11100053
B18: Depreciation%Sales | D18: ='Historical Financial Statement'!D24/'Historical Financial Statement'!D6 -> 0.027490234 | E18: ='Historical Financial Statement'!E24/'Historical Financial Statement'!E6 -> 0.026954751 | F18: ='Historical Financial Statement'!F24/'Historical Financial Statement'!F6 -> 0.028453629 | G18: ='Historical Financial Statement'!G24/'Historical Financial Statement'!G6 -> 0.028891645 | H18: ='Historical Financial Statement'!H24/'Historical Financial Statement'!H6 -> 0.033306066 | I18: ='Historical Financial Statement'!I24/'Historical Financial Statement'!I6 -> 0.033407941 | J18: ='Historical Financial Statement'!J24/'Historical Financial Statement'!J6 -> 0.028566628 | K18: ='Historical Financial Statement'!K24/'Historical Financial Statement'!K6 -> 0.025508104 | ... M18: ='Historical Financial Statement'!M24/'Historical Financial Statement'!M6 -> 0.021856705 | O18: =AVERAGE(D18:M18) -> 0.027678233 | P18: =MEDIAN(D18:M18) -> 0.027971931
B20: Return on Capital Employed | D20: =('Historical Financial Statement'!D18-'Historical Financial Statement'!D24)/('Historical Financial Statement'!D47+'Historical Financial Statement'!D48+'Historical Financial Statement'!D49) -> 0.31461767 | E20: =('Historical Financial Statement'!E18-'Historical Financial Statement'!E24)/('Historical Financial Statement'!E47+'Historical Financial Statement'!E48+'Historical Financial Statement'!E49) -> 0.30816048 | F20: =('Historical Financial Statement'!F18-'Historical Financial Statement'!F24)/('Historical Financial Statement'!F47+'Historical Financial Statement'!F48+'Historical Financial Statement'!F49) -> 0.29087469 | G20: =('Historical Financial Statement'!G18-'Historical Financial Statement'!G24)/('Historical Financial Statement'!G47+'Historical Financial Statement'!G48+'Historical Financial Statement'!G49) -> 0.28976384 | H20: =('Historical Financial Statement'!H18-'Historical Financial Statement'!H24)/('Historical Financial Statement'!H47+'Historical Financial Statement'!H48+'Historical Financial Statement'!H49) -> 0.26999906 | I20: =('Historical Financial Statement'!I18-'Historical Financial Statement'!I24)/('Historical Financial Statement'!I47+'Historical Financial Statement'!I48+'Historical Financial Statement'!I49) -> 0.25436581 | J20: =('Historical Financial Statement'!J18-'Historical Financial Statement'!J24)/('Historical Financial Statement'!J47+'Historical Financial Statement'!J48+'Historical Financial Statement'!J49) -> 0.30126365 | K20: =('Historical Financial Statement'!K18-'Historical Financial Statement'!K24)/('Historical Financial Statement'!K47+'Historical Financial Statement'!K48+'Historical Financial Statement'!K49) -> 0.3440081 | ... M20: =('Historical Financial Statement'!M18-'Historical Financial Statement'!M24)/('Historical Financial Statement'!M47+'Historical Financial Statement'!M48+'Historical Financial Statement'!M49) -> 0.34406984 | O20: =AVERAGE(D20:M20) -> 0.30335159 | P20: =MEDIAN(D20:M20) -> 0.30471206
B21: Retained Earnings% | D21: ='Historical Financial Statement'!D44 -> 0.14687786 | E21: ='Historical Financial Statement'!E44 -> 0.33819421 | F21: ='Historical Financial Statement'!F44 -> 0.3207286 | G21: ='Historical Financial Statement'!G44 -> 0.34463984 | H21: ='Historical Financial Statement'!H44 -> 0.053044068 | I21: ='Historical Financial Statement'!I44 -> 0 | J21: ='Historical Financial Statement'!J44 -> 0 | K21: ='Historical Financial Statement'!K44 -> 0 | ... M21: ='Historical Financial Statement'!M44 -> 0 | O21: =AVERAGE(D21:M21) -> 0.12180906 | P21: =MEDIAN(D21:M21) -> 0.03382504
B22: Return on Equity% | D22: ='Historical Financial Statement'!D33/('Historical Financial Statement'!D47+'Historical Financial Statement'!D48) -> 0.18785942 | E22: ='Historical Financial Statement'!E33/('Historical Financial Statement'!E47+'Historical Financial Statement'!E48) -> 0.18784852 | F22: ='Historical Financial Statement'!F33/('Historical Financial Statement'!F47+'Historical Financial Statement'!F48) -> 0.17621121 | G22: ='Historical Financial Statement'!G33/('Historical Financial Statement'!G47+'Historical Financial Statement'!G48) -> 0.18186171 | H22: ='Historical Financial Statement'!H33/('Historical Financial Statement'!H47+'Historical Financial Statement'!H48) -> 0.2018508 | I22: ='Historical Financial Statement'!I33/('Historical Financial Statement'!I47+'Historical Financial Statement'!I48) -> 0.17906224 | J22: ='Historical Financial Statement'!J33/('Historical Financial Statement'!J47+'Historical Financial Statement'!J48) -> 0.21764928 | K22: ='Historical Financial Statement'!K33/('Historical Financial Statement'!K47+'Historical Financial Statement'!K48) -> 0.25130525 | ... M22: ='Historical Financial Statement'!M33/('Historical Financial Statement'!M47+'Historical Financial Statement'!M48) -> 0.24643135 | O22: =AVERAGE(D22:M22) -> 0.20638955 | P22: =MEDIAN(D22:M22) -> 0.19485511
B23: Self Sustained Growth Rate | D23: =D21*D22 -> 0.027592391 | E23: =E21*E22 -> 0.063529279 | F23: =F21*F22 -> 0.056515974 | G23: =G21*G22 -> 0.062676792 | H23: =H21*H22 -> 0.010706988 | I23: =I21*I22 -> 0 | J23: =J21*J22 -> 0 | K23: =K21*K22 -> 0 | ... M23: =M21*M22 -> 0 | O23: =AVERAGE(D23:M23) -> 0.022443654 | P23: =MEDIAN(D23:M23) -> 0.0070610516
B24: Interest Coverage Ratio | D24: =('Historical Financial Statement'!D18-'Historical Financial Statement'!D24)/'Historical Financial Statement'!D21 -> 172.20133 | E24: =('Historical Financial Statement'!E18-'Historical Financial Statement'!E24)/'Historical Financial Statement'!E21 -> 291.99918 | F24: =('Historical Financial Statement'!F18-'Historical Financial Statement'!F24)/'Historical Financial Statement'!F21 -> 132.89549 | G24: =('Historical Financial Statement'!G18-'Historical Financial Statement'!G24)/'Historical Financial Statement'!G21 -> 240.06695 | H24: =('Historical Financial Statement'!H18-'Historical Financial Statement'!H24)/'Historical Financial Statement'!H21 -> 217.48132 | I24: =('Historical Financial Statement'!I18-'Historical Financial Statement'!I24)/'Historical Financial Statement'!I21 -> 265.98568 | J24: =('Historical Financial Statement'!J18-'Historical Financial Statement'!J24)/'Historical Financial Statement'!J21 -> 314.89815 | K24: =('Historical Financial Statement'!K18-'Historical Financial Statement'!K24)/'Historical Financial Statement'!K21 -> 307.25537 | ... M24: =('Historical Financial Statement'!M18-'Historical Financial Statement'!M24)/'Historical Financial Statement'!M21 -> 536.90923 | O24: =AVERAGE(D24:M24) -> 308.48955 | P24: =MEDIAN(D24:M24) -> 278.99243
B26: Debitor Turnover Ratio | D26: ='Historical Financial Statement'!D6/'Historical Financial Statement'!D59 -> 20.442577 | E26: ='Historical Financial Statement'!E6/'Historical Financial Statement'!E59 -> 17.284797 | F26: ='Historical Financial Statement'!F6/'Historical Financial Statement'!F59 -> 16.19845 | G26: ='Historical Financial Statement'!G6/'Historical Financial Statement'!G59 -> 11.979238 | H26: ='Historical Financial Statement'!H6/'Historical Financial Statement'!H59 -> 19.273399 | I26: ='Historical Financial Statement'!I6/'Historical Financial Statement'!I59 -> 19.689591 | J26: ='Historical Financial Statement'!J6/'Historical Financial Statement'!J59 -> 24.633226 | K26: ='Historical Financial Statement'!K6/'Historical Financial Statement'!K59 -> 23.990173 | ... M26: ='Historical Financial Statement'!M6/'Historical Financial Statement'!M59 -> 15.959451 | O26: =AVERAGE(D26:M26) -> 18.632497 | P26: =MEDIAN(D26:M26) -> 18.279098
B27: Creditor Turnover Ratio | D27: ='Historical Financial Statement'!D6/'Historical Financial Statement'!D50 -> 4.4095324 | E27: ='Historical Financial Statement'!E6/'Historical Financial Statement'!E50 -> 4.5306245 | F27: ='Historical Financial Statement'!F6/'Historical Financial Statement'!F50 -> 3.7152199 | G27: ='Historical Financial Statement'!G6/'Historical Financial Statement'!G50 -> 3.8411297 | H27: ='Historical Financial Statement'!H6/'Historical Financial Statement'!H50 -> 4.1996201 | I27: ='Historical Financial Statement'!I6/'Historical Financial Statement'!I50 -> 3.7479256 | J27: ='Historical Financial Statement'!J6/'Historical Financial Statement'!J50 -> 4.1849768 | K27: ='Historical Financial Statement'!K6/'Historical Financial Statement'!K50 -> 4.3323459 | ... M27: ='Historical Financial Statement'!M6/'Historical Financial Statement'!M50 -> 4.2584165 | O27: =AVERAGE(D27:M27) -> 4.1229104 | P27: =MEDIAN(D27:M27) -> 4.1922984
B28: Inventory Turnover Ratio | D28: ='Historical Financial Statement'!D6/'Historical Financial Statement'!D60 -> 4.3248364 | E28: ='Historical Financial Statement'!E6/'Historical Financial Statement'!E60 -> 5.2694767 | F28: ='Historical Financial Statement'!F6/'Historical Financial Statement'!F60 -> 5.7969871 | G28: ='Historical Financial Statement'!G6/'Historical Financial Statement'!G60 -> 6.1504181 | H28: ='Historical Financial Statement'!H6/'Historical Financial Statement'!H60 -> 5.5620976 | I28: ='Historical Financial Statement'!I6/'Historical Financial Statement'!I60 -> 4.737587 | J28: ='Historical Financial Statement'!J6/'Historical Financial Statement'!J60 -> 5.5820787 | K28: ='Historical Financial Statement'!K6/'Historical Financial Statement'!K60 -> 6.0248123 | ... M28: ='Historical Financial Statement'!M6/'Historical Financial Statement'!M60 -> 4.8168218 | O28: =AVERAGE(D28:M28) -> 5.3064983 | P28: =MEDIAN(D28:M28) -> 5.4157872
B29: Fixed Asset Turnover Ratio | D29: ='Historical Financial Statement'!D6/'Historical Financial Statement'!D53 -> 2.5943642 | E29: ='Historical Financial Statement'!E6/'Historical Financial Statement'!E53 -> 2.6908896 | F29: ='Historical Financial Statement'!F6/'Historical Financial Statement'!F53 -> 2.6294508 | G29: ='Historical Financial Statement'!G6/'Historical Financial Statement'!G53 -> 2.4950504 | H29: ='Historical Financial Statement'!H6/'Historical Financial Statement'!H53 -> 2.2745326 | I29: ='Historical Financial Statement'!I6/'Historical Financial Statement'!I53 -> 2.1141916 | J29: ='Historical Financial Statement'!J6/'Historical Financial Statement'!J53 -> 2.5027058 | K29: ='Historical Financial Statement'!K6/'Historical Financial Statement'!K53 -> 2.743348 | ... M29: ='Historical Financial Statement'!M6/'Historical Financial Statement'!M53 -> 3.4308292 | O29: =AVERAGE(D29:M29) -> 2.5917181 | P29: =MEDIAN(D29:M29) -> 2.548535
B30: Capital Turnover Ratio | D30: ='Historical Financial Statement'!D6/('Historical Financial Statement'!D47+'Historical Financial Statement'!D48) -> 0.91828821 | E30: ='Historical Financial Statement'!E6/('Historical Financial Statement'!E47+'Historical Financial Statement'!E48) -> 0.92145874 | F30: ='Historical Financial Statement'!F6/('Historical Financial Statement'!F47+'Historical Financial Statement'!F48) -> 0.82743952 | G30: ='Historical Financial Statement'!G6/('Historical Financial Statement'!G47+'Historical Financial Statement'!G48) -> 0.81736336 | H30: ='Historical Financial Statement'!H6/('Historical Financial Statement'!H47+'Historical Financial Statement'!H48) -> 0.7566299 | I30: ='Historical Financial Statement'!I6/('Historical Financial Statement'!I47+'Historical Financial Statement'!I48) -> 0.81623233 | J30: ='Historical Financial Statement'!J6/('Historical Financial Statement'!J47+'Historical Financial Statement'!J48) -> 0.97100291 | K30: ='Historical Financial Statement'!K6/('Historical Financial Statement'!K47+'Historical Financial Statement'!K48) -> 1.0255045 | ... M30: ='Historical Financial Statement'!M6/('Historical Financial Statement'!M47+'Historical Financial Statement'!M48) -> 1.075586 | O30: =AVERAGE(D30:M30) -> 0.90412579 | P30: =MEDIAN(D30:M30) -> 0.91502033
B32: Debtor Days | D32: =365/D26 -> 17.854892 | E32: =365/E26 -> 21.116823 | F32: =365/F26 -> 22.53302 | G32: =365/G26 -> 30.469383 | H32: =365/H26 -> 18.938019 | I32: =365/I26 -> 18.537714 | J32: =365/J26 -> 14.817385 | K32: =365/K26 -> 15.214563 | ... M32: =365/M26 -> 22.870462 | O32: =AVERAGE(D32:M32) -> 20.398309 | P32: =MEDIAN(D32:M32) -> 20.027421
B33: Creditor Days | D33: =365/D27 -> 82.775217 | E33: =365/E27 -> 80.562845 | F33: =365/F27 -> 98.24452 | G33: =365/G27 -> 95.024128 | H33: =365/H27 -> 86.912624 | I33: =365/I27 -> 97.387204 | J33: =365/J27 -> 87.216733 | K33: =365/K27 -> 84.249966 | ... M33: =365/M27 -> 85.712611 | O33: =AVERAGE(D33:M33) -> 88.912391 | P33: =MEDIAN(D33:M33) -> 87.064678
B34: Inventory Days | D34: =365/D28 -> 84.396256 | E34: =365/E28 -> 69.26684 | F34: =365/F28 -> 62.963742 | G34: =365/G28 -> 59.345559 | H34: =365/H28 -> 65.622725 | I34: =365/I28 -> 77.04344 | J34: =365/J28 -> 65.387828 | K34: =365/K28 -> 60.5828 | ... M34: =365/M28 -> 75.776106 | O34: =AVERAGE(D34:M34) -> 69.642907 | P34: =MEDIAN(D34:M34) -> 67.444782
